Script started on Thu Feb  3 19:06:03 2022

The default interactive shell is now zsh.
To update your account to use zsh, please run `chsh -s /bin/zsh`.
For more details, please visit https://support.apple.com/kb/HT208050.
[?1034hbash-3.2$ python3 3_procesos.py 
Valor inicial del contador 0
Traceback (most recent call last):
  File "<string>", line 1, in <module>
  File "/Users/cati/opt/anaconda3/lib/python3.8/multiprocessing/spawn.py", line 116, in spawn_main
Traceback (most recent call last):
  File "<string>", line 1, in <module>
  File "/Users/cati/opt/anaconda3/lib/python3.8/multiprocessing/spawn.py", line 116, in spawn_main
    exitcode = _main(fd, parent_sentinel)
  File "/Users/cati/opt/anaconda3/lib/python3.8/multiprocessing/spawn.py", line 126, in _main
    self = reduction.pickle.load(from_parent)
  File "/Users/cati/opt/anaconda3/lib/python3.8/multiprocessing/synchronize.py", line 110, in __setstate__
    exitcode = _main(fd, parent_sentinel)
  File "/Users/cati/opt/anaconda3/lib/python3.8/multiprocessing/spawn.py", line 126, in _main
    self = reduction.pickle.load(from_parent)
  File "/Users/cati/opt/anaconda3/lib/python3.8/multiprocessing/synchronize.py", line 110, in __setstate__
    self._semlock = _multiprocessing.SemLock._rebuild(*state)
FileNotFoundError: [Errno 2] No such file or directory
Traceback (most recent call last):
  File "<string>", line 1, in <module>
  File "/Users/cati/opt/anaconda3/lib/python3.8/multiprocessing/spawn.py", line 116, in spawn_main
    exitcode = _main(fd, parent_sentinel)
  File "/Users/cati/opt/anaconda3/lib/python3.8/multiprocessing/spawn.py", line 126, in _main
    self = reduction.pickle.load(from_parent)
  File "/Users/cati/opt/anaconda3/lib/python3.8/multiprocessing/synchronize.py", line 110, in __setstate__
    self._semlock = _multiprocessing.SemLock._rebuild(*state)
FileNotFoundError: [Errno 2] No such file or directory
    self._semlock = _multiprocessing.SemLock._rebuild(*state)
FileNotFoundError: [Errno 2] No such file or directory
Traceback (most recent call last):
  File "<string>", line 1, in <module>
  File "/Users/cati/opt/anaconda3/lib/python3.8/multiprocessing/spawn.py", line 116, in spawn_main
    exitcode = _main(fd, parent_sentinel)
  File "/Users/cati/opt/anaconda3/lib/python3.8/multiprocessing/spawn.py", line 126, in _main
    self = reduction.pickle.load(from_parent)
  File "/Users/cati/opt/anaconda3/lib/python3.8/multiprocessing/synchronize.py", line 110, in __setstate__
    self._semlock = _multiprocessing.SemLock._rebuild(*state)
FileNotFoundError: [Errno 2] No such file or directory
Traceback (most recent call last):
  File "<string>", line 1, in <module>
Traceback (most recent call last):
  File "<string>", line 1, in <module>
  File "/Users/cati/opt/anaconda3/lib/python3.8/multiprocessing/spawn.py", line 116, in spawn_main
  File "/Users/cati/opt/anaconda3/lib/python3.8/multiprocessing/spawn.py", line 116, in spawn_main
    exitcode = _main(fd, parent_sentinel)
  File "/Users/cati/opt/anaconda3/lib/python3.8/multiprocessing/spawn.py", line 126, in _main
    exitcode = _main(fd, parent_sentinel)
  File "/Users/cati/opt/anaconda3/lib/python3.8/multiprocessing/spawn.py", line 126, in _main
    self = reduction.pickle.load(from_parent)
  File "/Users/cati/opt/anaconda3/lib/python3.8/multiprocessing/synchronize.py", line 110, in __setstate__
    self = reduction.pickle.load(from_parent)
  File "/Users/cati/opt/anaconda3/lib/python3.8/multiprocessing/synchronize.py", line 110, in __setstate__
    self._semlock = _multiprocessing.SemLock._rebuild(*state)
FileNotFoundError: [Errno 2] No such file or directory
    self._semlock = _multiprocessing.SemLock._rebuild(*state)
FileNotFoundError: [Errno 2] No such file or directory
Traceback (most recent call last):
  File "<string>", line 1, in <module>
  File "/Users/cati/opt/anaconda3/lib/python3.8/multiprocessing/spawn.py", line 116, in spawn_main
    exitcode = _main(fd, parent_sentinel)
  File "/Users/cati/opt/anaconda3/lib/python3.8/multiprocessing/spawn.py", line 126, in _main
    self = reduction.pickle.load(from_parent)
  File "/Users/cati/opt/anaconda3/lib/python3.8/multiprocessing/synchronize.py", line 110, in __setstate__
    self._semlock = _multiprocessing.SemLock._rebuild(*state)
FileNotFoundError: [Errno 2] No such file or directory
Traceback (most recent call last):
  File "<string>", line 1, in <module>
  File "/Users/cati/opt/anaconda3/lib/python3.8/multiprocessing/spawn.py", line 116, in spawn_main
    exitcode = _main(fd, parent_sentinel)
  File "/Users/cati/opt/anaconda3/lib/python3.8/multiprocessing/spawn.py", line 126, in _main
    self = reduction.pickle.load(from_parent)
  File "/Users/cati/opt/anaconda3/lib/python3.8/multiprocessing/synchronize.py", line 110, in __setstate__
    self._semlock = _multiprocessing.SemLock._rebuild(*state)
FileNotFoundError: [Errno 2] No such file or directory
bash-3.2$ python3 3_procesos.py 
Valor inicial del contador 0
Traceback (most recent call last):
  File "<string>", line 1, in <module>
  File "/Users/cati/opt/anaconda3/lib/python3.8/multiprocessing/spawn.py", line 116, in spawn_main
    exitcode = _main(fd, parent_sentinel)
  File "/Users/cati/opt/anaconda3/lib/python3.8/multiprocessing/spawn.py", line 126, in _main
    self = reduction.pickle.load(from_parent)
  File "/Users/cati/opt/anaconda3/lib/python3.8/multiprocessing/synchronize.py", line 110, in __setstate__
    self._semlock = _multiprocessing.SemLock._rebuild(*state)
FileNotFoundError: [Errno 2] No such file or directory
Traceback (most recent call last):
  File "<string>", line 1, in <module>
  File "/Users/cati/opt/anaconda3/lib/python3.8/multiprocessing/spawn.py", line 116, in spawn_main
    exitcode = _main(fd, parent_sentinel)
  File "/Users/cati/opt/anaconda3/lib/python3.8/multiprocessing/spawn.py", line 126, in _main
    self = reduction.pickle.load(from_parent)
  File "/Users/cati/opt/anaconda3/lib/python3.8/multiprocessing/synchronize.py", line 110, in __setstate__
    self._semlock = _multiprocessing.SemLock._rebuild(*state)
FileNotFoundError: [Errno 2] No such file or directory
Traceback (most recent call last):
  File "<string>", line 1, in <module>
  File "/Users/cati/opt/anaconda3/lib/python3.8/multiprocessing/spawn.py", line 116, in spawn_main
    exitcode = _main(fd, parent_sentinel)
  File "/Users/cati/opt/anaconda3/lib/python3.8/multiprocessing/spawn.py", line 126, in _main
    self = reduction.pickle.load(from_parent)
  File "/Users/cati/opt/anaconda3/lib/python3.8/multiprocessing/synchronize.py", line 110, in __setstate__
    self._semlock = _multiprocessing.SemLock._rebuild(*state)
FileNotFoundError: [Errno 2] No such file or directory
Traceback (most recent call last):
  File "<string>", line 1, in <module>
  File "/Users/cati/opt/anaconda3/lib/python3.8/multiprocessing/spawn.py", line 116, in spawn_main
    exitcode = _main(fd, parent_sentinel)
  File "/Users/cati/opt/anaconda3/lib/python3.8/multiprocessing/spawn.py", line 126, in _main
    self = reduction.pickle.load(from_parent)
  File "/Users/cati/opt/anaconda3/lib/python3.8/multiprocessing/synchronize.py", line 110, in __setstate__
    self._semlock = _multiprocessing.SemLock._rebuild(*state)
FileNotFoundError: [Errno 2] No such file or directory
Traceback (most recent call last):
  File "<string>", line 1, in <module>
  File "/Users/cati/opt/anaconda3/lib/python3.8/multiprocessing/spawn.py", line 116, in spawn_main
    exitcode = _main(fd, parent_sentinel)
  File "/Users/cati/opt/anaconda3/lib/python3.8/multiprocessing/spawn.py", line 126, in _main
    self = reduction.pickle.load(from_parent)
  File "/Users/cati/opt/anaconda3/lib/python3.8/multiprocessing/synchronize.py", line 110, in __setstate__
    self._semlock = _multiprocessing.SemLock._rebuild(*state)
FileNotFoundError: [Errno 2] No such file or directory
Traceback (most recent call last):
  File "<string>", line 1, in <module>
  File "/Users/cati/opt/anaconda3/lib/python3.8/multiprocessing/spawn.py", line 116, in spawn_main
    exitcode = _main(fd, parent_sentinel)
  File "/Users/cati/opt/anaconda3/lib/python3.8/multiprocessing/spawn.py", line 126, in _main
    self = reduction.pickle.load(from_parent)
  File "/Users/cati/opt/anaconda3/lib/python3.8/multiprocessing/synchronize.py", line 110, in __setstate__
    self._semlock = _multiprocessing.SemLock._rebuild(*state)
FileNotFoundError: [Errno 2] No such file or directory
Traceback (most recent call last):
  File "<string>", line 1, in <module>
  File "/Users/cati/opt/anaconda3/lib/python3.8/multiprocessing/spawn.py", line 116, in spawn_main
    exitcode = _main(fd, parent_sentinel)
  File "/Users/cati/opt/anaconda3/lib/python3.8/multiprocessing/spawn.py", line 126, in _main
    self = reduction.pickle.load(from_parent)
  File "/Users/cati/opt/anaconda3/lib/python3.8/multiprocessing/synchronize.py", line 110, in __setstate__
    self._semlock = _multiprocessing.SemLock._rebuild(*state)
FileNotFoundError: [Errno 2] No such file or directory
Traceback (most recent call last):
  File "<string>", line 1, in <module>
  File "/Users/cati/opt/anaconda3/lib/python3.8/multiprocessing/spawn.py", line 116, in spawn_main
    exitcode = _main(fd, parent_sentinel)
  File "/Users/cati/opt/anaconda3/lib/python3.8/multiprocessing/spawn.py", line 126, in _main
    self = reduction.pickle.load(from_parent)
  File "/Users/cati/opt/anaconda3/lib/python3.8/multiprocessing/synchronize.py", line 110, in __setstate__
    self._semlock = _multiprocessing.SemLock._rebuild(*state)
FileNotFoundError: [Errno 2] No such file or directory
bash-3.2$ v[Kgit add 3_procesos.py 
bash-3.2$ git commit -m "ejecucion [K_ [Kproceso2[K3"
[main 8821140] ejecucion_proceso3
 Committer: Siria Catherine IÃ±iguez Brito <cati@Air-de-Siria.home>
Your name and email address were configured automatically based
on your username and hostname. Please check that they are accurate.
You can suppress this message by setting them explicitly:

    git config --global user.name "Your Name"
    git config --global user.email you@example.com

After doing this, you may fix the identity used for this commit with:

    git commit --amend --reset-author

 1 file changed, 26 insertions(+)
 create mode 100644 3_procesos.py
bash-3.2$ git push
Enumerating objects: 4, done.
Counting objects:  25% (1/4)Counting objects:  50% (2/4)Counting objects:  75% (3/4)Counting objects: 100% (4/4)Counting objects: 100% (4/4), done.
Delta compression using up to 4 threads
Compressing objects:  33% (1/3)Compressing objects:  66% (2/3)Compressing objects: 100% (3/3)Compressing objects: 100% (3/3), done.
Writing objects:  33% (1/3)Writing objects:  66% (2/3)Writing objects: 100% (3/3)Writing objects: 100% (3/3), 661 bytes | 661.00 KiB/s, done.
Total 3 (delta 1), reused 0 (delta 0), pack-reused 0
remote: Resolving deltas:   0% (0/1)[Kremote: Resolving deltas: 100% (1/1)[Kremote: Resolving deltas: 100% (1/1), completed with 1 local object.[K
To github.com:Siria-Iniguez/Primer-Repositorio.git
   81c1e67..8821140  main -> main
bash-3.2$ git add multiprocessing